#include <iostream>
#include <exception>

void func()
{
	std::cout << "func cagrildi\n";
	try
	{
		throw std::runtime_error{ "error from func\n" };
	}
	catch (const std::exception& ex)
	{
		std::cout << ex.what() << '\n';
	}
}

int main()
{
	std::thread t{ func };  // exception caught
	t.join();
}
